Traceback (most recent call last):
  File "C:\Users\shinki\Anaconda3\lib\site-packages\jupyter_cache\executors\utils.py", line 51, in single_nb_execution
    executenb(
  File "C:\Users\shinki\Anaconda3\lib\site-packages\nbclient\client.py", line 1112, in execute
    return NotebookClient(nb=nb, resources=resources, km=km, **kwargs).execute()
  File "C:\Users\shinki\Anaconda3\lib\site-packages\nbclient\util.py", line 74, in wrapped
    return just_run(coro(*args, **kwargs))
  File "C:\Users\shinki\Anaconda3\lib\site-packages\nbclient\util.py", line 53, in just_run
    return loop.run_until_complete(coro)
  File "C:\Users\shinki\Anaconda3\lib\asyncio\base_events.py", line 642, in run_until_complete
    return future.result()
  File "C:\Users\shinki\Anaconda3\lib\site-packages\nbclient\client.py", line 553, in async_execute
    await self.async_execute_cell(
  File "C:\Users\shinki\Anaconda3\lib\site-packages\nbclient\client.py", line 857, in async_execute_cell
    self._check_raise_for_error(cell, exec_reply)
  File "C:\Users\shinki\Anaconda3\lib\site-packages\nbclient\client.py", line 760, in _check_raise_for_error
    raise CellExecutionError.from_cell_and_msg(cell, exec_reply_content)
nbclient.exceptions.CellExecutionError: An error occurred while executing the following cell:
------------------
c1_list = [11,12,13,14,15]
c2_list = ['a','a','b','c','d'] # Í∞íÏóê Ï§ëÎ≥µÏù¥ ÏûàÏùå
df = pd.DataFrame({'c1': c1_list, 'c2': c2_list})
df.set_index('c2', verify_integrity=True) # index Ï§ëÎ≥µÏó¨Î∂ÄÎ•º Ï≤¥ÌÅ¨
------------------

[1;31m---------------------------------------------------------------------------[0m
[1;31mValueError[0m                                Traceback (most recent call last)
[1;32m~\AppData\Local\Temp\ipykernel_67628\2078573242.py[0m in [0;36m<module>[1;34m[0m
[0;32m      2[0m [0mc2_list[0m [1;33m=[0m [1;33m[[0m[1;34m'a'[0m[1;33m,[0m[1;34m'a'[0m[1;33m,[0m[1;34m'b'[0m[1;33m,[0m[1;34m'c'[0m[1;33m,[0m[1;34m'd'[0m[1;33m][0m [1;31m# Í∞íÏóê Ï§ëÎ≥µÏù¥ ÏûàÏùå[0m[1;33m[0m[1;33m[0m[0m
[0;32m      3[0m [0mdf[0m [1;33m=[0m [0mpd[0m[1;33m.[0m[0mDataFrame[0m[1;33m([0m[1;33m{[0m[1;34m'c1'[0m[1;33m:[0m [0mc1_list[0m[1;33m,[0m [1;34m'c2'[0m[1;33m:[0m [0mc2_list[0m[1;33m}[0m[1;33m)[0m[1;33m[0m[1;33m[0m[0m
[1;32m----> 4[1;33m [0mdf[0m[1;33m.[0m[0mset_index[0m[1;33m([0m[1;34m'c2'[0m[1;33m,[0m [0mverify_integrity[0m[1;33m=[0m[1;32mTrue[0m[1;33m)[0m [1;31m# index Ï§ëÎ≥µÏó¨Î∂ÄÎ•º Ï≤¥ÌÅ¨[0m[1;33m[0m[1;33m[0m[0m
[0m
[1;32m~\Anaconda3\lib\site-packages\pandas\util\_decorators.py[0m in [0;36mwrapper[1;34m(*args, **kwargs)[0m
[0;32m    309[0m                     [0mstacklevel[0m[1;33m=[0m[0mstacklevel[0m[1;33m,[0m[1;33m[0m[1;33m[0m[0m
[0;32m    310[0m                 )
[1;32m--> 311[1;33m             [1;32mreturn[0m [0mfunc[0m[1;33m([0m[1;33m*[0m[0margs[0m[1;33m,[0m [1;33m**[0m[0mkwargs[0m[1;33m)[0m[1;33m[0m[1;33m[0m[0m
[0m[0;32m    312[0m [1;33m[0m[0m
[0;32m    313[0m         [1;32mreturn[0m [0mwrapper[0m[1;33m[0m[1;33m[0m[0m

[1;32m~\Anaconda3\lib\site-packages\pandas\core\frame.py[0m in [0;36mset_index[1;34m(self, keys, drop, append, inplace, verify_integrity)[0m
[0;32m   5508[0m         [1;32mif[0m [0mverify_integrity[0m [1;32mand[0m [1;32mnot[0m [0mindex[0m[1;33m.[0m[0mis_unique[0m[1;33m:[0m[1;33m[0m[1;33m[0m[0m
[0;32m   5509[0m             [0mduplicates[0m [1;33m=[0m [0mindex[0m[1;33m[[0m[0mindex[0m[1;33m.[0m[0mduplicated[0m[1;33m([0m[1;33m)[0m[1;33m][0m[1;33m.[0m[0munique[0m[1;33m([0m[1;33m)[0m[1;33m[0m[1;33m[0m[0m
[1;32m-> 5510[1;33m             [1;32mraise[0m [0mValueError[0m[1;33m([0m[1;34mf"Index has duplicate keys: {duplicates}"[0m[1;33m)[0m[1;33m[0m[1;33m[0m[0m
[0m[0;32m   5511[0m [1;33m[0m[0m
[0;32m   5512[0m         [1;31m# use set to handle duplicate column names gracefully in case of drop[0m[1;33m[0m[1;33m[0m[0m

[1;31mValueError[0m: Index has duplicate keys: Index(['a'], dtype='object', name='c2')
ValueError: Index has duplicate keys: Index(['a'], dtype='object', name='c2')

